Workbook
Name CalFirst: DATE(Calendar!$E$5,calMonthNum,1)
Name calMonthNum: MATCH(Calendar!$C$5,lstMonths,0)
Name CalStart: CalFirst-WEEKDAY(CalFirst,2)+1
Name DoneStatus: INDEX(tblStatus[Status],ROWS(tblStatus[Status]))
Name lstMembers: tblTeam[Name]
Name lstMonths: tblMonths[Month]
Name lstPriority: tblPriority[Priority]
Name lstProjects: tblProjects[Project]
Name lstStatus: tblStatus[Status]
Name MaxCards: 25
Name Slicer_Owner: #N/A
Name Slicer_Priority: #N/A
Name Slicer_Project: #N/A
Name Slicer_Status: #N/A

Sheet Home
B2: TeamBoard
B3: Projects, tasks, boards and live team activity - all in one shared workbook.
B4: =TEXT(TODAY(),"dddd, d mmmm yyyy")&" · "&COUNTA(tblTasks[Task])&" tasks · "&COUNTA(tblProjects[Project])&" projects · "&COUNTA(tblTeam[Name])&" teammates · "&COUNTIFS(tblTasks[State],"Overdue")&" overdue" -> Saturday, 17 October 2026 · 41 tasks · 7 projects · 10 teammates · 13 overdue
B8: Where do you want to go?
B9: 📊 Dashboard | E9: 🗂 Board | H9: 💬 Room | K9: 👤 My Work
B10: KPIs, charts and health | E10: Kanban lanes by status | H10: Live feed & team chat | K10: Your personal to-do list
B13: 📅 Calendar | E13: 🏆 Scorecards | H13: ✅ Tasks | K13: 📁 Projects
B14: Tasks by due date | E14: Team & project scores | H14: Add & update tasks | K14: Add & track projects
B18: How it works
B19: 1 Add your team | E19: 2 Create projects | H19: 3 Add tasks | K19: 4 Move work along
B20: Team sheet: one row per person (name, email, role). | E20: Projects sheet: add a row - it pops up in the Room. | H20: Tasks sheet: type under the table, use the dropdowns. | K20: Change a task's Status - its card moves on the Board.
B22: Legend
B23: Header | C23: Blue column header = you type here (dropdowns help). | H23: Dashboard, Board, Room, My Work, Calendar = views only.
B24: Header | C24: Grey column header = calculated automatically - don't type. | H24: Sample data is included - overwrite or delete those rows when you start.
B26: Share it: save to OneDrive or SharePoint → Share → give your team 'Can edit'. Everyone sees changes live in Excel for the web or the Excel app (Microsoft 365). No macros - works for free in the browser.

Sheet Dashboard
B2: Team Dashboard | O2: ⌂ Home
B3: Live from the Tasks sheet · click the slicers to filter every chart, card and list | L3: ="Updated "&TEXT(NOW(),"ddd d mmm, h:mm AM/PM") -> Updated Sat 17 Oct, 9:11 AM
B5: FILTERS | J5: =IF(Calc!C58<COUNTA(tblTasks[Task]),"🔎 Filtered: showing "&Calc!C58&" of "&COUNTA(tblTasks[Task])&" tasks - clear slicers to see all","Showing all "&COUNTA(tblTasks[Task])&" tasks") -> Showing all 41 tasks
B12: TOTAL TASKS | D12: OPEN | F12: COMPLETED | H12: OVERDUE | J12: DUE IN 7 DAYS | L12: BLOCKED | N12: TEAM SCORE
B13: =Calc!C58 -> 41 | D13: {=COUNTIFS(tblTasks[Visible],1,tblTasks[Status],"<>"&DoneStatus,tblTasks[Task],"<>")} -> 41 | F13: =Calc!C60 -> 0 | H13: =COUNTIFS(tblTasks[Visible],1,tblTasks[State],"Overdue") -> 13 | J13: =COUNTIFS(tblTasks[Visible],1,tblTasks[State],"Due soon") -> 14 | L13: {=COUNTIFS(tblTasks[Visible],1,tblTasks[Status],INDEX(lstStatus,4))} -> 2 | N13: {=IFERROR(ROUND(AVERAGE(_xlfn._xlws.FILTER(_xlfn.ANCHORARRAY(Scorecards!I8),_xlfn.ANCHORARRAY(Scorecards!I8)<>"")),0),0)} -> 14
B14: {="across "&COUNTA(_xlfn.UNIQUE(_xlfn._xlws.FILTER(tblTasks[Project],(tblTasks[Visible]=1)*(tblTasks[Task]<>""),"")))&" projects"} -> across 7 projects | D14: {=COUNTIFS(tblTasks[Visible],1,tblTasks[Status],INDEX(lstStatus,2))&" in progress"} -> 9 in progress | F14: =Calc!C59&" tasks done" -> 0 tasks done | H14: ="need attention now" -> need attention now | J14: ="coming up this week" -> coming up this week | L14: ="waiting on someone" -> waiting on someone | N14: =REPT("★",ROUND(N13/20,0))&REPT("☆",5-ROUND(N13/20,0)) -> ★☆☆☆☆
B54: 🔥 Needs attention | E54: Overdue or Urgent tasks that are still open (top 10)
B55: ID | C55: PRIORITY | D55: DUE | E55: STATE | F55: OWNER | G55: PROJECT | H55: TASK
B56: {=_xlfn.LET(_xlpm.m,(tblTasks[Visible]=1)*(tblTasks[Task]<>"")*(((tblTasks[State]="Overdue")+(tblTasks[Priority]="Urgent")*(tblTasks[Status]<>DoneStatus))>0),IFERROR(_xlfn.TAKE(_xlfn.SORTBY(_xlfn._xlws.FILTER(_xlfn.HSTACK(tblTasks[ID],tblTasks[Priority],tblTasks[Due Date],tblTasks[State],tblTasks[Owner],IFERROR(_xlfn.XLOOKUP(tblTasks[Project],tblProjects[Project],tblProjects[Code]),"OPS"),tblTasks[Task]),_xlpm.m),_xlfn._xlws.FILTER(tblTasks[DueKey],_xlpm.m),1),10),"🎉 Nothing needs attention right now"))} -> T-010 | C56: High | D56: 46292 | E56: Overdue | F56: Lina Park | G56: MKT | H56: Campaign brief & goals
B57: T-016 | C57: Urgent | D57: 46296 | E57: Overdue | F57: Ravi Kumar | G57: MKT | H57: Budget approval
B58: T-001 | C58: High | D58: 46300 | E58: Overdue | F58: Nora Fischer | G58: WEB | H58: Finalize homepage wireframes
B59: T-023 | C59: Normal | D59: 46301 | E59: Overdue | F59: Tom Becker | G59: APP | H59: Crash reporting setup
B60: T-026 | C60: High | D60: 46302 | E60: Overdue | F60: Maya Chen | G60: ONB | H60: Map current onboarding journey
B61: T-020 | C61: Normal | D61: 46304 | E61: Overdue | F61: Nora Fischer | G61: APP | H61: Dark theme UI
B62: T-035 | C62: Low | D62: 46305 | E62: Overdue | F62: Sara Ali | G62: OPS | H62: Weekly team sync notes
B63: T-038 | C63: Normal | D63: 46307 | E63: Overdue | F63: Jack Moore | G63: OPS | H63: Dashboard data clean-up
B64: T-040 | C64: High | D64: 46308 | E64: Overdue | F64: Jack Moore | G64: OPS | H64: Customer churn analysis
B65: T-008 | C65: Low | D65: 46309 | E65: Overdue | F65: Diego Santos | G65: WEB | H65: Optimize image loading
B68: 📁 Project health | I68: 🔥 Who's working on what
B69: HEALTH | C69: PROGRESS | D69: DONE | E69: OVERDUE | F69: PROJECT | I69: MEMBER | J69: {=UPPER(TRANSPOSE(lstStatus))} -> #VALUE! | O69: OPEN
B70: {=IFERROR(_xlfn.HSTACK(tblProjects[Health],tblProjects[Progress],tblProjects[Done]&" / "&tblProjects[Tasks],tblProjects[Overdue],tblProjects[Project]),"")} -> ⛔ Off Track | C70: 0 | D70: 0 / 9 | E70: 3 | F70: Website Redesign | I70: {=lstMembers} -> Sara Ali | J70: {=COUNTIFS(tblTasks[Owner],_xlfn.ANCHORARRAY(I70),tblTasks[Status],TRANSPOSE(lstStatus),tblTasks[Visible],1)} -> #VALUE! | O70: {=COUNTIFS(tblTasks[Owner],_xlfn.ANCHORARRAY(I70),tblTasks[Status],"<>"&DoneStatus,tblTasks[Visible],1)} -> 4
B71: ⛔ Off Track | C71: 0 | D71: 0 / 8 | E71: 3 | F71: Q4 Marketing Campaign | I71: Omar Haddad | O71: 2
B72: ⛔ Off Track | C72: 0 | D72: 0 / 8 | E72: 3 | F72: Mobile App v2 | I72: Lina Park | O72: 3
B73: ⚠ At Risk | C73: 0 | D73: 0 / 6 | E73: 1 | F73: Customer Onboarding | I73: Jack Moore | O73: 5
B74: ⛔ Off Track | C74: 0 | D74: 0 / 6 | E74: 3 | F74: General / Ops | I74: Maya Chen | O74: 4
B75: ✅ On Track | C75: 0 | D75: 0 / 3 | E75: 0 | F75: Annual Report 2026 | I75: Ravi Kumar | O75: 3
B76: ✅ On Track | C76: 0 | D76: 0 / 1 | E76: 0 | F76: ExCon | I76: Nora Fischer | O76: 6
I77: Diego Santos | O77: 4
I78: Aisha Bello | O78: 6
I79: Tom Becker | O79: 4
B86: Tip: slicers filter the Tasks table for everyone editing at the same moment - clear them when you're done (the ⨯ icon on each slicer).

Sheet Board
B2: Board | O2: ⌂ Home
B3: Kanban view of every task · change a task's Status on the Tasks sheet and its card moves here instantly
C5: 🔍 SEARCH CARDS | F5: FILTERS (shared with the Dashboard - type a word in Search and press Enter)
C8: ＋ Add or edit tasks on the Tasks sheet
B11: {=UPPER(INDEX(lstStatus,1))&" "&COUNTIFS(tblTasks[Status],INDEX(lstStatus,1),tblTasks[Visible],1,tblTasks[Task],"<>")} -> TO DO 14 | E11: {=UPPER(INDEX(lstStatus,2))&" "&COUNTIFS(tblTasks[Status],INDEX(lstStatus,2),tblTasks[Visible],1,tblTasks[Task],"<>")} -> IN PROGRESS 9 | H11: {=UPPER(INDEX(lstStatus,3))&" "&COUNTIFS(tblTasks[Status],INDEX(lstStatus,3),tblTasks[Visible],1,tblTasks[Task],"<>")} -> REVIEW 5 | K11: {=UPPER(INDEX(lstStatus,4))&" "&COUNTIFS(tblTasks[Status],INDEX(lstStatus,4),tblTasks[Visible],1,tblTasks[Task],"<>")} -> BLOCKED 2 | N11: {=UPPER(INDEX(lstStatus,5))&" "&COUNTIFS(tblTasks[Status],INDEX(lstStatus,5),tblTasks[Visible],1,tblTasks[Task],"<>")} -> DONE 10
B13: {=_xlfn.LET(_xlpm.st,INDEX(lstStatus,1),_xlpm.kw,TRIM($C$6),_xlpm.m,(tblTasks[Status]=_xlpm.st)*(tblTasks[Visible]=1)*(tblTasks[Task]<>"")*IF(_xlpm.kw="",1,ISNUMBER(SEARCH(_xlpm.kw,tblTasks[Task]&" "&tblTasks[Tags]&" "&tblTasks[Owner]&" "&tblTasks[Project]))),_xlpm.d,IFERROR(_xlfn.SORTBY(_xlfn._xlws.FILTER(_xlfn.HSTACK(tblTasks[Priority],tblTasks[Card]),_xlpm.m),_xlfn._xlws.FILTER(tblTasks[SortKey],_xlpm.m),1),""),_xlpm.n,MIN(ROWS(_xlpm.d),MaxCards),IF(INDEX(_xlpm.d,1,1)="","",_xlfn.LET(_xlpm.r,_xlfn.SEQUENCE(2*_xlpm.n-1),IF(MOD(_xlpm.r,2)=1,INDEX(_xlpm.d,(_xlpm.r+1)/2,{1,2}),""))))} -> Urgent | C13: QA signup flow on mobile 👤 Tom Becker 📅 16 Oct ⚠ OVERDUE [WEB] #qa #mobile | E13: {=_xlfn.LET(_xlpm.st,INDEX(lstStatus,2),_xlpm.kw,TRIM($C$6),_xlpm.m,(tblTasks[Status]=_xlpm.st)*(tblTasks[Visible]=1)*(tblTasks[Task]<>"")*IF(_xlpm.kw="",1,ISNUMBER(SEARCH(_xlpm.kw,tblTasks[Task]&" "&tblTasks[Tags]&" "&tblTasks[Owner]&" "&tblTasks[Project]))),_xlpm.d,IFERROR(_xlfn.SORTBY(_xlfn._xlws.FILTER(_xlfn.HSTACK(tblTasks[Priority],tblTasks[Card]),_xlpm.m),_xlfn._xlws.FILTER(tblTasks[SortKey],_xlpm.m),1),""),_xlpm.n,MIN(ROWS(_xlpm.d),MaxCards),IF(INDEX(_xlpm.d,1,1)="","",_xlfn.LET(_xlpm.r,_xlfn.SEQUENCE(2*_xlpm.n-1),IF(MOD(_xlpm.r,2)=1,INDEX(_xlpm.d,(_xlpm.r+1)/2,{1,2}),""))))} -> Urgent | F13: Vendor contract renewal 👤 Ravi Kumar 📅 18 Oct [OPS] #finance · 50% done | H13: {=_xlfn.LET(_xlpm.st,INDEX(lstStatus,3),_xlpm.kw,TRIM($C$6),_xlpm.m,(tblTasks[Status]=_xlpm.st)*(tblTasks[Visible]=1)*(tblTasks[Task]<>"")*IF(_xlpm.kw="",1,ISNUMBER(SEARCH(_xlpm.kw,tblTasks[Task]&" "&tblTasks[Tags]&" "&tblTasks[Owner]&" "&tblTasks[Project]))),_xlpm.d,IFERROR(_xlfn.SORTBY(_xlfn._xlws.FILTER(_xlfn.HSTACK(tblTasks[Priority],tblTasks[Card]),_xlpm.m),_xlfn._xlws.FILTER(tblTasks[SortKey],_xlpm.m),1),""),_xlpm.n,MIN(ROWS(_xlpm.d),MaxCards),IF(INDEX(_xlpm.d,1,1)="","",_xlfn.LET(_xlpm.r,_xlfn.SEQUENCE(2*_xlpm.n-1),IF(MOD(_xlpm.r,2)=1,INDEX(_xlpm.d,(_xlpm.r+1)/2,{1,2}),""))))} -> High | I13: Push notification service 👤 Omar Haddad 📅 17 Oct [APP] #backend · 90% done | K13: {=_xlfn.LET(_xlpm.st,INDEX(lstStatus,4),_xlpm.kw,TRIM($C$6),_xlpm.m,(tblTasks[Status]=_xlpm.st)*(tblTasks[Visible]=1)*(tblTasks[Task]<>"")*IF(_xlpm.kw="",1,ISNUMBER(SEARCH(_xlpm.kw,tblTasks[Task]&" "&tblTasks[Tags]&" "&tblTasks[Owner]&" "&tblTasks[Project]))),_xlpm.d,IFERROR(_xlfn.SORTBY(_xlfn._xlws.FILTER(_xlfn.HSTACK(tblTasks[Priority],tblTasks[Card]),_xlpm.m),_xlfn._xlws.FILTER(tblTasks[SortKey],_xlpm.m),1),""),_xlpm.n,MIN(ROWS(_xlpm.d),MaxCards),IF(INDEX(_xlpm.d,1,1)="","",_xlfn.LET(_xlpm.r,_xlfn.SEQUENCE(2*_xlpm.n-1),IF(MOD(_xlpm.r,2)=1,INDEX(_xlpm.d,(_xlpm.r+1)/2,{1,2}),""))))} -> High | L13: Landing page A/B test 👤 Jack Moore 📅 15 Oct ⚠ OVERDUE [MKT] #data #web · 20% done | N13: {=_xlfn.LET(_xlpm.st,INDEX(lstStatus,5),_xlpm.kw,TRIM($C$6),_xlpm.m,(tblTasks[Status]=_xlpm.st)*(tblTasks[Visible]=1)*(tblTasks[Task]<>"")*IF(_xlpm.kw="",1,ISNUMBER(SEARCH(_xlpm.kw,tblTasks[Task]&" "&tblTasks[Tags]&" "&tblTasks[Owner]&" "&tblTasks[Project]))),_xlpm.d,IFERROR(_xlfn.SORTBY(_xlfn._xlws.FILTER(_xlfn.HSTACK(tblTasks[Priority],tblTasks[Card]),_xlpm.m),_xlfn._xlws.FILTER(tblTasks[SortKey],_xlpm.m),1),""),_xlpm.n,MIN(ROWS(_xlpm.d),MaxCards),IF(INDEX(_xlpm.d,1,1)="","",_xlfn.LET(_xlpm.r,_xlfn.SEQUENCE(2*_xlpm.n-1),IF(MOD(_xlpm.r,2)=1,INDEX(_xlpm.d,(_xlpm.r+1)/2,{1,2}),""))))} -> Urgent | O13: Budget approval 👤 Ravi Kumar 📅 1 Oct ⚠ OVERDUE [MKT] #finance · 100% done
B15: High | C15: Beta tester feedback round 👤 Maya Chen 📅 14 Oct ⚠ OVERDUE [APP] #feedback | E15: Urgent | F15: Offline sync engine 👤 Omar Haddad 📅 21 Oct [APP] #core · 70% done | H15: High | I15: Q4 hiring plan 👤 Sara Ali 📅 22 Oct [OPS] #people · 70% done | K15: Normal | L15: Migrate blog to new CMS 👤 Diego Santos 📅 25 Oct [WEB] #backend · 30% done | N15: High | O15: Campaign brief & goals 👤 Lina Park 📅 27 Sep ⚠ OVERDUE [MKT] #strategy · 100% done
B17: High | C17: Collect department KPIs 👤 Ravi Kumar 📅 31 Oct [RPT] #finance | E17: High | F17: Customer churn analysis 👤 Jack Moore 📅 13 Oct ⚠ OVERDUE [OPS] #data · 60% done | H17: Normal | I17: Write pricing page copy 👤 Aisha Bello 📅 18 Oct [WEB] #copy · 90% done | N17: High | O17: Finalize homepage wireframes 👤 Nora Fischer 📅 5 Oct ⚠ OVERDUE [WEB] #design · 100% done
B19: High | C19: In-app product tour 👤 Diego Santos 📅 6 Nov [ONB] #frontend | E19: High | F19: Build new pricing page 👤 Diego Santos 📅 20 Oct [WEB] #frontend · 60% done | H19: Normal | I19: Social media calendar 👤 Lina Park 📅 19 Oct [MKT] #social · 80% done | N19: High | O19: Map current onboarding journey 👤 Maya Chen 📅 7 Oct ⚠ OVERDUE [ONB] #research · 100% done
B21: High | C21: Launch-day checklist 👤 Sara Ali 📅 8 Nov [WEB] #launch | E21: High | F21: Holiday email sequence 👤 Aisha Bello 📅 23 Oct [MKT] #email · 50% done | H21: Normal | I21: Onboarding success metrics 👤 Jack Moore 📅 21 Oct [ONB] #data · 80% done | N21: Normal | O21: Crash reporting setup 👤 Tom Becker 📅 6 Oct ⚠ OVERDUE [APP] #qa · 100% done
B23: Normal | C23: Paid ads creative 👤 Nora Fischer 📅 27 Oct [MKT] #ads #design | E23: High | F23: Regression test suite 👤 Tom Becker 📅 24 Oct [APP] #qa · 50% done | N23: Normal | O23: Dark theme UI 👤 Nora Fischer 📅 9 Oct ⚠ OVERDUE [APP] #design · 100% done
B25: Normal | C25: Release notes v2.0 👤 Aisha Bello 📅 27 Oct [APP] #docs | E25: Normal | F25: Customer interview round 👤 Maya Chen 📅 19 Oct [ONB] #research · 50% done | N25: Normal | O25: Dashboard data clean-up 👤 Jack Moore 📅 12 Oct ⚠ OVERDUE [OPS] #data · 100% done
B27: Normal | C27: Press release draft 👤 Aisha Bello 📅 29 Oct [MKT] #pr | E27: Normal | F27: Set up analytics events 👤 Jack Moore 📅 22 Oct [WEB] #data · 40% done | N27: Normal | O27: Kickoff & timeline 👤 Sara Ali 📅 17 Oct [RPT] #planning · 100% done
B29: Normal | C29: Accessibility audit 👤 Nora Fischer 📅 31 Oct [WEB] #a11y | E29: Normal | F29: Welcome email series 👤 Aisha Bello 📅 26 Oct [ONB] #email · 30% done | N29: Low | O29: Weekly team sync notes 👤 Sara Ali 📅 10 Oct ⚠ OVERDUE [OPS] #ops · 100% done
B31: Normal | C31: Security awareness training 👤 Tom Becker 📅 2 Nov [OPS] #it | N31: Low | O31: Optimize image loading 👤 Diego Santos 📅 14 Oct ⚠ OVERDUE [WEB] #performance · 100% done
B33: Normal | C33: Report design template 👤 Nora Fischer 📅 21 Nov [RPT] #design
B35: Low | C35: App store screenshots 👤 Nora Fischer 📅 26 Oct [APP] #store
B37: Low | C37: Influencer shortlist 👤 Lina Park 📅 4 Nov [MKT] #partners
B39: Low | C39: Help center refresh 👤 Aisha Bello 📅 16 Nov [ONB] #docs
C64: Cards are sorted by priority, then due date. Colored edge = priority (red Urgent · amber High · indigo Normal · grey Low). Up to 25 cards per lane.

Sheet Room
B2: Team Room | K2: ⌂ Home
B3: Everything that happens, live: new projects, new tasks, completed work and team messages
B5: {="TODAY · 🆕 "&COUNTIFS(tblTasks[Added On],TODAY())&" new tasks ✅ "&COUNTIFS(tblTasks[Completed On],TODAY())&" completed 🚀 "&COUNTIFS(tblProjects[Added On],TODAY())&" new projects 💬 "&COUNTIFS(tblChat[When],">="&TODAY(),tblChat[When],"<"&(TODAY()+1))&" messages 📅 "&COUNTIFS(tblTasks[Due Date],TODAY(),tblTasks[Status],"<>"&DoneStatus)&" due today"} -> TODAY · 🆕 5 new tasks ✅ 1 completed 🚀 2 new projects 💬 5 messages 📅 2 due today
B7: 🚀 NEWEST PROJECT | H7: 🆕 LATEST TASK
B8: {=IFERROR(_xlfn.TAKE(tblProjects[Project],-1)&" ["&_xlfn.TAKE(tblProjects[Code],-1)&"]"&CHAR(10)&"Owner: "&_xlfn.TAKE(tblProjects[Owner],-1)&" · Target: "&TEXT(_xlfn.TAKE(tblProjects[Target Date],-1),"d mmm yyyy")&CHAR(10)&_xlfn.TAKE(tblProjects[Description],-1),"No projects yet")} -> ExCon [UPA] Owner: Maya Chen · Target: 17 Jan 2027 Critical Preparation | H8: {=IFERROR(_xlfn.TAKE(tblTasks[ID],-1)&" · "&_xlfn.TAKE(tblTasks[Task],-1)&CHAR(10)&"Owner: "&_xlfn.TAKE(tblTasks[Owner],-1)&" · "&_xlfn.TAKE(tblTasks[Project],-1)&CHAR(10)&"Status: "&_xlfn.TAKE(tblTasks[Status],-1)&" · Priority: "&_xlfn.TAKE(tblTasks[Priority],-1),"No tasks yet")} -> T-041 · 1st Priority task Owner: Maya Chen · ExCon Status: Back Log · Priority: High
B10: 📡 Activity feed (newest first) | H10: ✍ Post to the room
H11: Type in the first empty row under this table. When: press Ctrl+; then space then Ctrl+Shift+; (date + time).
B12: WHEN | D12: WHO | E12: WHAT HAPPENED | F12: DATE | H12: When | I12: Who | J12: Message | K12: About
B13: {=_xlfn.LET(_xlpm.icon,_xlfn.LAMBDA(_xlpm.col,_xlpm.txt,IF(LEN(_xlpm.col)>=0,_xlpm.txt)),_xlpm.tA,IFERROR(_xlfn._xlws.FILTER(_xlfn.HSTACK(tblTasks[Added On],_xlpm.icon(tblTasks[Task],"🆕"),tblTasks[Added By],"added task “"&tblTasks[Task]&"” to "&tblTasks[Project]),(tblTasks[Task]<>"")*ISNUMBER(tblTasks[Added On])),{0,"","",""}),_xlpm.tC,IFERROR(_xlfn._xlws.FILTER(_xlfn.HSTACK(tblTasks[Completed On],_xlpm.icon(tblTasks[Task],"✅"),tblTasks[Owner],"completed “"&tblTasks[Task]&"”"),(tblTasks[Status]=DoneStatus)*ISNUMBER(tblTasks[Completed On])),{0,"","",""}),_xlpm.tP,IFERROR(_xlfn._xlws.FILTER(_xlfn.HSTACK(tblProjects[Added On],_xlpm.icon(tblProjects[Project],"🚀"),tblProjects[Added By],"launched project “"&tblProjects[Project]&"” · target "&TEXT(tblProjects[Target Date],"d mmm")),(tblProjects[Project]<>"")*ISNUMBER(tblProjects[Added On])),{0,"","",""}),_xlpm.tM,IFERROR(_xlfn._xlws.FILTER(_xlfn.HSTACK(tblChat[When],_xlpm.icon(tblChat[Message],"💬"),tblChat[Who],tblChat[Message]&IF(tblChat[About]="",""," · re: "&tblChat[About])),(tblChat[Message]<>"")*ISNUMBER(tblChat[When])),{0,"","",""}),_xlpm.all,_xlfn.VSTACK(_xlpm.tA,_xlpm.tC,_xlpm.tP,_xlpm.tM),_xlpm.f,_xlfn._xlws.FILTER(_xlpm.all,INDEX(_xlpm.all,,1)>0,{0,"","",""}),_xlpm.t,_xlfn.TAKE(_xlfn.SORTBY(_xlpm.f,INDEX(_xlpm.f,,1),-1),40),_xlpm.w,INDEX(_xlpm.t,,1),_xlpm.ago,TODAY()-INT(_xlpm.w),IF(_xlpm.w=0,"",_xlfn.HSTACK(IF(_xlpm.ago=0,"Today",IF(_xlpm.ago=1,"Yesterday",_xlpm.ago&" days ago")),_xlfn.DROP(_xlpm.t,,1),TEXT(_xlpm.w,IF(MOD(_xlpm.w,1)=0,"ddd d mmm","ddd d mmm, h:mm")))))} -> Today | C13: 💬 | D13: Nora Fischer | E13: Dark theme shipped. Screenshots for the store are next. · re: App store screenshots | F13: Sat 17 Oct, 15:48 | H13: 46311.583 | I13: Sara Ali | J13: Welcome to the Team Room! Post updates here so everyone sees them live.
B14: Today | C14: 💬 | D14: Diego Santos | E14: Pricing page is on staging, feedback welcome! · re: Build new pricing page | F14: Sat 17 Oct, 15:20 | H14: 46311.667 | I14: Omar Haddad | J14: Offline sync is passing all tests on Android, iOS next. | K14: Offline sync engine
B15: Today | C15: 💬 | D15: Maya Chen | E15: Interviews booked with 6 customers this week. · re: Customer interview round | F15: Sat 17 Oct, 14:25 | H15: 46311.833 | I15: Lina Park | J15: Need final sign-off on the holiday email subject lines by Monday. | K15: Holiday email sequence
B16: Today | C16: 💬 | D16: Ravi Kumar | E16: Kicked off the Annual Report 2026 project - KPIs due in two weeks. · re: Annual Report 2026 | F16: Sat 17 Oct, 13:00 | H16: 46312.458 | I16: Tom Becker | J16: Signup flow breaks on small screens - logging details now. | K16: QA signup flow on mobile
B17: Today | C17: 💬 | D17: Tom Becker | E17: Signup flow breaks on small screens - logging details now. · re: QA signup flow on mobile | F17: Sat 17 Oct, 11:00 | H17: 46312.542 | I17: Ravi Kumar | J17: Kicked off the Annual Report 2026 project - KPIs due in two weeks. | K17: Annual Report 2026
B18: Today | C18: 🆕 | D18: Aisha Bello | E18: added task “Release notes v2.0” to Mobile App v2 | F18: Sat 17 Oct | H18: 46312.601 | I18: Maya Chen | J18: Interviews booked with 6 customers this week. | K18: Customer interview round
B19: Today | C19: 🆕 | D19: Sara Ali | E19: added task “Kickoff & timeline” to Annual Report 2026 | F19: Sat 17 Oct | H19: 46312.639 | I19: Diego Santos | J19: Pricing page is on staging, feedback welcome! | K19: Build new pricing page
B20: Today | C20: 🆕 | D20: Sara Ali | E20: added task “Collect department KPIs” to Annual Report 2026 | F20: Sat 17 Oct | H20: 46312.658 | I20: Nora Fischer | J20: Dark theme shipped. Screenshots for the store are next. | K20: App store screenshots
B21: Today | C21: 🆕 | D21: Nora Fischer | E21: added task “Report design template” to Annual Report 2026 | F21: Sat 17 Oct
B22: Today | C22: 🆕 | D22: Ravi Kumar | E22: added task “1st Priority task” to ExCon | F22: Sat 17 Oct
B23: Today | C23: 🚀 | D23: Sara Ali | E23: launched project “Annual Report 2026” · target 26 Dec | F23: Sat 17 Oct
B24: Today | C24: 🚀 | D24: Jack Moore | E24: launched project “ExCon” · target 17 Jan | F24: Sat 17 Oct
B25: Yesterday | C25: 💬 | D25: Lina Park | E25: Need final sign-off on the holiday email subject lines by Monday. · re: Holiday email sequence | F25: Fri 16 Oct, 20:00
B26: Yesterday | C26: 💬 | D26: Omar Haddad | E26: Offline sync is passing all tests on Android, iOS next. · re: Offline sync engine | F26: Fri 16 Oct, 16:00
B27: Yesterday | C27: 💬 | D27: Sara Ali | E27: Welcome to the Team Room! Post updates here so everyone sees them live. | F27: Fri 16 Oct, 14:00
B28: Yesterday | C28: 🆕 | D28: Sara Ali | E28: added task “Press release draft” to Q4 Marketing Campaign | F28: Fri 16 Oct
B29: 2 days ago | C29: 🆕 | D29: Sara Ali | E29: added task “Launch-day checklist” to Website Redesign | F29: Thu 15 Oct
B30: 3 days ago | C30: 🆕 | D30: Aisha Bello | E30: added task “Help center refresh” to Customer Onboarding | F30: Wed 14 Oct
B31: 4 days ago | C31: 🆕 | D31: Sara Ali | E31: added task “App store screenshots” to Mobile App v2 | F31: Tue 13 Oct
B32: 4 days ago | C32: 🆕 | D32: Sara Ali | E32: added task “Security awareness training” to General / Ops | F32: Tue 13 Oct
... B52: 19 days ago | C52: 🆕 | D52: Maya Chen | E52: added task “Map current onboarding journey” to Customer Onboarding | F52: Mon 28 Sep

Sheet My Work
B2: My Work | K2: ⌂ Home
B3: Your personal to-do list across every project · pick your name below
B5: I AM | C5: Diego Santos | D5: ◀ click the cell and use the dropdown arrow. (Everyone shares this cell - each person just picks their own name.)
B7: 📋 My open tasks
B8: ID | C8: TASK | D8: PROJECT | E8: STATUS | F8: PRIORITY | G8: DUE | H8: DAYS | I8: STATE
B9: {=_xlfn.LET(_xlpm.me,$C$5,_xlpm.m,(tblTasks[Owner]=_xlpm.me)*(tblTasks[Status]<>DoneStatus)*(tblTasks[Task]<>""),IFERROR(_xlfn.SORTBY(_xlfn._xlws.FILTER(_xlfn.HSTACK(tblTasks[ID],tblTasks[Task],tblTasks[Project],tblTasks[Status],tblTasks[Priority],tblTasks[Due Date],tblTasks[Days Left],tblTasks[State]),_xlpm.m),_xlfn._xlws.FILTER(tblTasks[DueKey],_xlpm.m),1),"🎉 Nothing open - great job!"))} -> T-008 | C9: Optimize image loading | D9: Website Redesign | E9: Done | F9: Low | G9: 46309 | H9: -3 | I9: Overdue | K9: OPEN TASKS
B10: T-002 | C10: Build new pricing page | D10: Website Redesign | E10: In Progress | F10: High | G10: 46315 | H10: 3 | I10: Due soon | K10: {=COUNTIFS(tblTasks[Owner],$C$5,tblTasks[Status],"<>"&DoneStatus)} -> 4
B11: T-005 | C11: Migrate blog to new CMS | D11: Website Redesign | E11: Blocked | F11: Normal | G11: 46320 | H11: 8 | I11: On track | K11: {="across "&IFERROR(ROWS(_xlfn.UNIQUE(_xlfn._xlws.FILTER(tblTasks[Project],(tblTasks[Owner]=$C$5)*(tblTasks[Status]<>DoneStatus)))),0)&" projects"} -> across 2 projects
B12: T-028 | C12: In-app product tour | D12: Customer Onboarding | E12: To Do | F12: High | G12: 46332 | H12: 20 | I12: On track
K14: OVERDUE
K15: =COUNTIFS(tblTasks[Owner],$C$5,tblTasks[State],"Overdue") -> 1
K16: ="tackle these first" -> tackle these first
K19: DUE THIS WEEK
K20: =COUNTIFS(tblTasks[Owner],$C$5,tblTasks[State],"Due soon") -> 1
K21: ="in the next 7 days" -> in the next 7 days
K24: COMPLETED
K25: {=COUNTIFS(tblTasks[Owner],$C$5,tblTasks[Status],DoneStatus)} -> 0
K26: ="tasks finished" -> tasks finished
K29: MY SCORE
K30: {=IFERROR(_xlfn.XLOOKUP($C$5,_xlfn.ANCHORARRAY(Scorecards!B8),_xlfn.ANCHORARRAY(Scorecards!I8)),"-")} -> 15
B31: ✅ Recently completed | K31: {=IFERROR(_xlfn.XLOOKUP($C$5,_xlfn.ANCHORARRAY(Scorecards!B8),_xlfn.ANCHORARRAY(Scorecards!J8))&" rank #"&_xlfn.XLOOKUP($C$5,_xlfn.ANCHORARRAY(Scorecards!B8),_xlfn.ANCHORARRAY(Scorecards!K8)),"")} -> ★☆☆☆☆ rank #3
B32: {=_xlfn.LET(_xlpm.me,$C$5,_xlpm.m,(tblTasks[Owner]=_xlpm.me)*(tblTasks[Status]=DoneStatus),IFERROR(_xlfn.TAKE(_xlfn.SORTBY(_xlfn._xlws.FILTER(_xlfn.HSTACK(tblTasks[ID],tblTasks[Task],tblTasks[Project],tblTasks[Completed On]),_xlpm.m),_xlfn._xlws.FILTER(tblTasks[Completed On],_xlpm.m),-1),5),"Nothing completed yet"))} -> Nothing completed yet

Sheet Calendar
B2: Calendar | H2: ⌂ Home
B3: Tasks by due date · ⚠ overdue ✓ done • open · Dashboard slicers apply here too
B5: MONTH ▸ | C5: October | D5: YEAR ▸ | E5: =YEAR(TODAY()) -> 2026 | F5: Pick another month/year to browse. Type =YEAR(TODAY()) back to follow today.
B7: MONDAY | C7: TUESDAY | D7: WEDNESDAY | E7: THURSDAY | F7: FRIDAY | G7: SATURDAY | H7: SUNDAY
B8: {=_xlfn.LET(_xlpm.d,CalStart+(ROW()-ROW($B$8))*7+COLUMN()-COLUMN($B$8),_xlpm.m,(tblTasks[Due Date]=_xlpm.d)*(tblTasks[Visible]=1)*(tblTasks[Task]<>""),_xlpm.n,SUM(_xlpm.m),_xlpm.t,IF(_xlpm.n=0,"",_xlfn.TEXTJOIN(CHAR(10),TRUE,_xlfn.TAKE(_xlfn._xlws.FILTER(IF(tblTasks[State]="Overdue","⚠ ",IF(tblTasks[Status]=DoneStatus,"✓ ","• "))&tblTasks[Task],_xlpm.m),3))),DAY(_xlpm.d)&IF(_xlpm.d=TODAY()," · TODAY","")&IF(_xlpm.n=0,"",CHAR(10)&_xlpm.t&IF(_xlpm.n>3,CHAR(10)&"+"&(_xlpm.n-3)&" more","")))} -> 28 | C8: {=_xlfn.LET(_xlpm.d,CalStart+(ROW()-ROW($B$8))*7+COLUMN()-COLUMN($B$8),_xlpm.m,(tblTasks[Due Date]=_xlpm.d)*(tblTasks[Visible]=1)*(tblTasks[Task]<>""),_xlpm.n,SUM(_xlpm.m),_xlpm.t,IF(_xlpm.n=0,"",_xlfn.TEXTJOIN(CHAR(10),TRUE,_xlfn.TAKE(_xlfn._xlws.FILTER(IF(tblTasks[State]="Overdue","⚠ ",IF(tblTasks[Status]=DoneStatus,"✓ ","• "))&tblTasks[Task],_xlpm.m),3))),DAY(_xlpm.d)&IF(_xlpm.d=TODAY()," · TODAY","")&IF(_xlpm.n=0,"",CHAR(10)&_xlpm.t&IF(_xlpm.n>3,CHAR(10)&"+"&(_xlpm.n-3)&" more","")))} -> 29 | D8: {=_xlfn.LET(_xlpm.d,CalStart+(ROW()-ROW($B$8))*7+COLUMN()-COLUMN($B$8),_xlpm.m,(tblTasks[Due Date]=_xlpm.d)*(tblTasks[Visible]=1)*(tblTasks[Task]<>""),_xlpm.n,SUM(_xlpm.m),_xlpm.t,IF(_xlpm.n=0,"",_xlfn.TEXTJOIN(CHAR(10),TRUE,_xlfn.TAKE(_xlfn._xlws.FILTER(IF(tblTasks[State]="Overdue","⚠ ",IF(tblTasks[Status]=DoneStatus,"✓ ","• "))&tblTasks[Task],_xlpm.m),3))),DAY(_xlpm.d)&IF(_xlpm.d=TODAY()," · TODAY","")&IF(_xlpm.n=0,"",CHAR(10)&_xlpm.t&IF(_xlpm.n>3,CHAR(10)&"+"&(_xlpm.n-3)&" more","")))} -> 30 | E8: {=_xlfn.LET(_xlpm.d,CalStart+(ROW()-ROW($B$8))*7+COLUMN()-COLUMN($B$8),_xlpm.m,(tblTasks[Due Date]=_xlpm.d)*(tblTasks[Visible]=1)*(tblTasks[Task]<>""),_xlpm.n,SUM(_xlpm.m),_xlpm.t,IF(_xlpm.n=0,"",_xlfn.TEXTJOIN(CHAR(10),TRUE,_xlfn.TAKE(_xlfn._xlws.FILTER(IF(tblTasks[State]="Overdue","⚠ ",IF(tblTasks[Status]=DoneStatus,"✓ ","• "))&tblTasks[Task],_xlpm.m),3))),DAY(_xlpm.d)&IF(_xlpm.d=TODAY()," · TODAY","")&IF(_xlpm.n=0,"",CHAR(10)&_xlpm.t&IF(_xlpm.n>3,CHAR(10)&"+"&(_xlpm.n-3)&" more","")))} -> 1 ⚠ Budget approval | F8: {=_xlfn.LET(_xlpm.d,CalStart+(ROW()-ROW($B$8))*7+COLUMN()-COLUMN($B$8),_xlpm.m,(tblTasks[Due Date]=_xlpm.d)*(tblTasks[Visible]=1)*(tblTasks[Task]<>""),_xlpm.n,SUM(_xlpm.m),_xlpm.t,IF(_xlpm.n=0,"",_xlfn.TEXTJOIN(CHAR(10),TRUE,_xlfn.TAKE(_xlfn._xlws.FILTER(IF(tblTasks[State]="Overdue","⚠ ",IF(tblTasks[Status]=DoneStatus,"✓ ","• "))&tblTasks[Task],_xlpm.m),3))),DAY(_xlpm.d)&IF(_xlpm.d=TODAY()," · TODAY","")&IF(_xlpm.n=0,"",CHAR(10)&_xlpm.t&IF(_xlpm.n>3,CHAR(10)&"+"&(_xlpm.n-3)&" more","")))} -> 2 | G8: {=_xlfn.LET(_xlpm.d,CalStart+(ROW()-ROW($B$8))*7+COLUMN()-COLUMN($B$8),_xlpm.m,(tblTasks[Due Date]=_xlpm.d)*(tblTasks[Visible]=1)*(tblTasks[Task]<>""),_xlpm.n,SUM(_xlpm.m),_xlpm.t,IF(_xlpm.n=0,"",_xlfn.TEXTJOIN(CHAR(10),TRUE,_xlfn.TAKE(_xlfn._xlws.FILTER(IF(tblTasks[State]="Overdue","⚠ ",IF(tblTasks[Status]=DoneStatus,"✓ ","• "))&tblTasks[Task],_xlpm.m),3))),DAY(_xlpm.d)&IF(_xlpm.d=TODAY()," · TODAY","")&IF(_xlpm.n=0,"",CHAR(10)&_xlpm.t&IF(_xlpm.n>3,CHAR(10)&"+"&(_xlpm.n-3)&" more","")))} -> 3 | H8: {=_xlfn.LET(_xlpm.d,CalStart+(ROW()-ROW($B$8))*7+COLUMN()-COLUMN($B$8),_xlpm.m,(tblTasks[Due Date]=_xlpm.d)*(tblTasks[Visible]=1)*(tblTasks[Task]<>""),_xlpm.n,SUM(_xlpm.m),_xlpm.t,IF(_xlpm.n=0,"",_xlfn.TEXTJOIN(CHAR(10),TRUE,_xlfn.TAKE(_xlfn._xlws.FILTER(IF(tblTasks[State]="Overdue","⚠ ",IF(tblTasks[Status]=DoneStatus,"✓ ","• "))&tblTasks[Task],_xlpm.m),3))),DAY(_xlpm.d)&IF(_xlpm.d=TODAY()," · TODAY","")&IF(_xlpm.n=0,"",CHAR(10)&_xlpm.t&IF(_xlpm.n>3,CHAR(10)&"+"&(_xlpm.n-3)&" more","")))} -> 4
B9: {=_xlfn.LET(_xlpm.d,CalStart+(ROW()-ROW($B$8))*7+COLUMN()-COLUMN($B$8),_xlpm.m,(tblTasks[Due Date]=_xlpm.d)*(tblTasks[Visible]=1)*(tblTasks[Task]<>""),_xlpm.n,SUM(_xlpm.m),_xlpm.t,IF(_xlpm.n=0,"",_xlfn.TEXTJOIN(CHAR(10),TRUE,_xlfn.TAKE(_xlfn._xlws.FILTER(IF(tblTasks[State]="Overdue","⚠ ",IF(tblTasks[Status]=DoneStatus,"✓ ","• "))&tblTasks[Task],_xlpm.m),3))),DAY(_xlpm.d)&IF(_xlpm.d=TODAY()," · TODAY","")&IF(_xlpm.n=0,"",CHAR(10)&_xlpm.t&IF(_xlpm.n>3,CHAR(10)&"+"&(_xlpm.n-3)&" more","")))} -> 5 ⚠ Finalize homepage wireframes | C9: {=_xlfn.LET(_xlpm.d,CalStart+(ROW()-ROW($B$8))*7+COLUMN()-COLUMN($B$8),_xlpm.m,(tblTasks[Due Date]=_xlpm.d)*(tblTasks[Visible]=1)*(tblTasks[Task]<>""),_xlpm.n,SUM(_xlpm.m),_xlpm.t,IF(_xlpm.n=0,"",_xlfn.TEXTJOIN(CHAR(10),TRUE,_xlfn.TAKE(_xlfn._xlws.FILTER(IF(tblTasks[State]="Overdue","⚠ ",IF(tblTasks[Status]=DoneStatus,"✓ ","• "))&tblTasks[Task],_xlpm.m),3))),DAY(_xlpm.d)&IF(_xlpm.d=TODAY()," · TODAY","")&IF(_xlpm.n=0,"",CHAR(10)&_xlpm.t&IF(_xlpm.n>3,CHAR(10)&"+"&(_xlpm.n-3)&" more","")))} -> 6 ⚠ Crash reporting setup | D9: {=_xlfn.LET(_xlpm.d,CalStart+(ROW()-ROW($B$8))*7+COLUMN()-COLUMN($B$8),_xlpm.m,(tblTasks[Due Date]=_xlpm.d)*(tblTasks[Visible]=1)*(tblTasks[Task]<>""),_xlpm.n,SUM(_xlpm.m),_xlpm.t,IF(_xlpm.n=0,"",_xlfn.TEXTJOIN(CHAR(10),TRUE,_xlfn.TAKE(_xlfn._xlws.FILTER(IF(tblTasks[State]="Overdue","⚠ ",IF(tblTasks[Status]=DoneStatus,"✓ ","• "))&tblTasks[Task],_xlpm.m),3))),DAY(_xlpm.d)&IF(_xlpm.d=TODAY()," · TODAY","")&IF(_xlpm.n=0,"",CHAR(10)&_xlpm.t&IF(_xlpm.n>3,CHAR(10)&"+"&(_xlpm.n-3)&" more","")))} -> 7 ⚠ Map current onboarding journey | E9: {=_xlfn.LET(_xlpm.d,CalStart+(ROW()-ROW($B$8))*7+COLUMN()-COLUMN($B$8),_xlpm.m,(tblTasks[Due Date]=_xlpm.d)*(tblTasks[Visible]=1)*(tblTasks[Task]<>""),_xlpm.n,SUM(_xlpm.m),_xlpm.t,IF(_xlpm.n=0,"",_xlfn.TEXTJOIN(CHAR(10),TRUE,_xlfn.TAKE(_xlfn._xlws.FILTER(IF(tblTasks[State]="Overdue","⚠ ",IF(tblTasks[Status]=DoneStatus,"✓ ","• "))&tblTasks[Task],_xlpm.m),3))),DAY(_xlpm.d)&IF(_xlpm.d=TODAY()," · TODAY","")&IF(_xlpm.n=0,"",CHAR(10)&_xlpm.t&IF(_xlpm.n>3,CHAR(10)&"+"&(_xlpm.n-3)&" more","")))} -> 8 | F9: {=_xlfn.LET(_xlpm.d,CalStart+(ROW()-ROW($B$8))*7+COLUMN()-COLUMN($B$8),_xlpm.m,(tblTasks[Due Date]=_xlpm.d)*(tblTasks[Visible]=1)*(tblTasks[Task]<>""),_xlpm.n,SUM(_xlpm.m),_xlpm.t,IF(_xlpm.n=0,"",_xlfn.TEXTJOIN(CHAR(10),TRUE,_xlfn.TAKE(_xlfn._xlws.FILTER(IF(tblTasks[State]="Overdue","⚠ ",IF(tblTasks[Status]=DoneStatus,"✓ ","• "))&tblTasks[Task],_xlpm.m),3))),DAY(_xlpm.d)&IF(_xlpm.d=TODAY()," · TODAY","")&IF(_xlpm.n=0,"",CHAR(10)&_xlpm.t&IF(_xlpm.n>3,CHAR(10)&"+"&(_xlpm.n-3)&" more","")))} -> 9 ⚠ Dark theme UI | G9: {=_xlfn.LET(_xlpm.d,CalStart+(ROW()-ROW($B$8))*7+COLUMN()-COLUMN($B$8),_xlpm.m,(tblTasks[Due Date]=_xlpm.d)*(tblTasks[Visible]=1)*(tblTasks[Task]<>""),_xlpm.n,SUM(_xlpm.m),_xlpm.t,IF(_xlpm.n=0,"",_xlfn.TEXTJOIN(CHAR(10),TRUE,_xlfn.TAKE(_xlfn._xlws.FILTER(IF(tblTasks[State]="Overdue","⚠ ",IF(tblTasks[Status]=DoneStatus,"✓ ","• "))&tblTasks[Task],_xlpm.m),3))),DAY(_xlpm.d)&IF(_xlpm.d=TODAY()," · TODAY","")&IF(_xlpm.n=0,"",CHAR(10)&_xlpm.t&IF(_xlpm.n>3,CHAR(10)&"+"&(_xlpm.n-3)&" more","")))} -> 10 ⚠ Weekly team sync notes | H9: {=_xlfn.LET(_xlpm.d,CalStart+(ROW()-ROW($B$8))*7+COLUMN()-COLUMN($B$8),_xlpm.m,(tblTasks[Due Date]=_xlpm.d)*(tblTasks[Visible]=1)*(tblTasks[Task]<>""),_xlpm.n,SUM(_xlpm.m),_xlpm.t,IF(_xlpm.n=0,"",_xlfn.TEXTJOIN(CHAR(10),TRUE,_xlfn.TAKE(_xlfn._xlws.FILTER(IF(tblTasks[State]="Overdue","⚠ ",IF(tblTasks[Status]=DoneStatus,"✓ ","• "))&tblTasks[Task],_xlpm.m),3))),DAY(_xlpm.d)&IF(_xlpm.d=TODAY()," · TODAY","")&IF(_xlpm.n=0,"",CHAR(10)&_xlpm.t&IF(_xlpm.n>3,CHAR(10)&"+"&(_xlpm.n-3)&" more","")))} -> 11
B10: {=_xlfn.LET(_xlpm.d,CalStart+(ROW()-ROW($B$8))*7+COLUMN()-COLUMN($B$8),_xlpm.m,(tblTasks[Due Date]=_xlpm.d)*(tblTasks[Visible]=1)*(tblTasks[Task]<>""),_xlpm.n,SUM(_xlpm.m),_xlpm.t,IF(_xlpm.n=0,"",_xlfn.TEXTJOIN(CHAR(10),TRUE,_xlfn.TAKE(_xlfn._xlws.FILTER(IF(tblTasks[State]="Overdue","⚠ ",IF(tblTasks[Status]=DoneStatus,"✓ ","• "))&tblTasks[Task],_xlpm.m),3))),DAY(_xlpm.d)&IF(_xlpm.d=TODAY()," · TODAY","")&IF(_xlpm.n=0,"",CHAR(10)&_xlpm.t&IF(_xlpm.n>3,CHAR(10)&"+"&(_xlpm.n-3)&" more","")))} -> 12 ⚠ Dashboard data clean-up | C10: {=_xlfn.LET(_xlpm.d,CalStart+(ROW()-ROW($B$8))*7+COLUMN()-COLUMN($B$8),_xlpm.m,(tblTasks[Due Date]=_xlpm.d)*(tblTasks[Visible]=1)*(tblTasks[Task]<>""),_xlpm.n,SUM(_xlpm.m),_xlpm.t,IF(_xlpm.n=0,"",_xlfn.TEXTJOIN(CHAR(10),TRUE,_xlfn.TAKE(_xlfn._xlws.FILTER(IF(tblTasks[State]="Overdue","⚠ ",IF(tblTasks[Status]=DoneStatus,"✓ ","• "))&tblTasks[Task],_xlpm.m),3))),DAY(_xlpm.d)&IF(_xlpm.d=TODAY()," · TODAY","")&IF(_xlpm.n=0,"",CHAR(10)&_xlpm.t&IF(_xlpm.n>3,CHAR(10)&"+"&(_xlpm.n-3)&" more","")))} -> 13 ⚠ Customer churn analysis | D10: {=_xlfn.LET(_xlpm.d,CalStart+(ROW()-ROW($B$8))*7+COLUMN()-COLUMN($B$8),_xlpm.m,(tblTasks[Due Date]=_xlpm.d)*(tblTasks[Visible]=1)*(tblTasks[Task]<>""),_xlpm.n,SUM(_xlpm.m),_xlpm.t,IF(_xlpm.n=0,"",_xlfn.TEXTJOIN(CHAR(10),TRUE,_xlfn.TAKE(_xlfn._xlws.FILTER(IF(tblTasks[State]="Overdue","⚠ ",IF(tblTasks[Status]=DoneStatus,"✓ ","• "))&tblTasks[Task],_xlpm.m),3))),DAY(_xlpm.d)&IF(_xlpm.d=TODAY()," · TODAY","")&IF(_xlpm.n=0,"",CHAR(10)&_xlpm.t&IF(_xlpm.n>3,CHAR(10)&"+"&(_xlpm.n-3)&" more","")))} -> 14 ⚠ Optimize image loading ⚠ Beta tester feedback round | E10: {=_xlfn.LET(_xlpm.d,CalStart+(ROW()-ROW($B$8))*7+COLUMN()-COLUMN($B$8),_xlpm.m,(tblTasks[Due Date]=_xlpm.d)*(tblTasks[Visible]=1)*(tblTasks[Task]<>""),_xlpm.n,SUM(_xlpm.m),_xlpm.t,IF(_xlpm.n=0,"",_xlfn.TEXTJOIN(CHAR(10),TRUE,_xlfn.TAKE(_xlfn._xlws.FILTER(IF(tblTasks[State]="Overdue","⚠ ",IF(tblTasks[Status]=DoneStatus,"✓ ","• "))&tblTasks[Task],_xlpm.m),3))),DAY(_xlpm.d)&IF(_xlpm.d=TODAY()," · TODAY","")&IF(_xlpm.n=0,"",CHAR(10)&_xlpm.t&IF(_xlpm.n>3,CHAR(10)&"+"&(_xlpm.n-3)&" more","")))} -> 15 ⚠ Landing page A/B test | F10: {=_xlfn.LET(_xlpm.d,CalStart+(ROW()-ROW($B$8))*7+COLUMN()-COLUMN($B$8),_xlpm.m,(tblTasks[Due Date]=_xlpm.d)*(tblTasks[Visible]=1)*(tblTasks[Task]<>""),_xlpm.n,SUM(_xlpm.m),_xlpm.t,IF(_xlpm.n=0,"",_xlfn.TEXTJOIN(CHAR(10),TRUE,_xlfn.TAKE(_xlfn._xlws.FILTER(IF(tblTasks[State]="Overdue","⚠ ",IF(tblTasks[Status]=DoneStatus,"✓ ","• "))&tblTasks[Task],_xlpm.m),3))),DAY(_xlpm.d)&IF(_xlpm.d=TODAY()," · TODAY","")&IF(_xlpm.n=0,"",CHAR(10)&_xlpm.t&IF(_xlpm.n>3,CHAR(10)&"+"&(_xlpm.n-3)&" more","")))} -> 16 ⚠ QA signup flow on mobile | G10: {=_xlfn.LET(_xlpm.d,CalStart+(ROW()-ROW($B$8))*7+COLUMN()-COLUMN($B$8),_xlpm.m,(tblTasks[Due Date]=_xlpm.d)*(tblTasks[Visible]=1)*(tblTasks[Task]<>""),_xlpm.n,SUM(_xlpm.m),_xlpm.t,IF(_xlpm.n=0,"",_xlfn.TEXTJOIN(CHAR(10),TRUE,_xlfn.TAKE(_xlfn._xlws.FILTER(IF(tblTasks[State]="Overdue","⚠ ",IF(tblTasks[Status]=DoneStatus,"✓ ","• "))&tblTasks[Task],_xlpm.m),3))),DAY(_xlpm.d)&IF(_xlpm.d=TODAY()," · TODAY","")&IF(_xlpm.n=0,"",CHAR(10)&_xlpm.t&IF(_xlpm.n>3,CHAR(10)&"+"&(_xlpm.n-3)&" more","")))} -> 17 · TODAY • Push notification service • Kickoff & timeline | H10: {=_xlfn.LET(_xlpm.d,CalStart+(ROW()-ROW($B$8))*7+COLUMN()-COLUMN($B$8),_xlpm.m,(tblTasks[Due Date]=_xlpm.d)*(tblTasks[Visible]=1)*(tblTasks[Task]<>""),_xlpm.n,SUM(_xlpm.m),_xlpm.t,IF(_xlpm.n=0,"",_xlfn.TEXTJOIN(CHAR(10),TRUE,_xlfn.TAKE(_xlfn._xlws.FILTER(IF(tblTasks[State]="Overdue","⚠ ",IF(tblTasks[Status]=DoneStatus,"✓ ","• "))&tblTasks[Task],_xlpm.m),3))),DAY(_xlpm.d)&IF(_xlpm.d=TODAY()," · TODAY","")&IF(_xlpm.n=0,"",CHAR(10)&_xlpm.t&IF(_xlpm.n>3,CHAR(10)&"+"&(_xlpm.n-3)&" more","")))} -> 18 • Write pricing page copy • Vendor contract renewal • 1st Priority task
B11: {=_xlfn.LET(_xlpm.d,CalStart+(ROW()-ROW($B$8))*7+COLUMN()-COLUMN($B$8),_xlpm.m,(tblTasks[Due Date]=_xlpm.d)*(tblTasks[Visible]=1)*(tblTasks[Task]<>""),_xlpm.n,SUM(_xlpm.m),_xlpm.t,IF(_xlpm.n=0,"",_xlfn.TEXTJOIN(CHAR(10),TRUE,_xlfn.TAKE(_xlfn._xlws.FILTER(IF(tblTasks[State]="Overdue","⚠ ",IF(tblTasks[Status]=DoneStatus,"✓ ","• "))&tblTasks[Task],_xlpm.m),3))),DAY(_xlpm.d)&IF(_xlpm.d=TODAY()," · TODAY","")&IF(_xlpm.n=0,"",CHAR(10)&_xlpm.t&IF(_xlpm.n>3,CHAR(10)&"+"&(_xlpm.n-3)&" more","")))} -> 19 • Social media calendar • Customer interview round | C11: {=_xlfn.LET(_xlpm.d,CalStart+(ROW()-ROW($B$8))*7+COLUMN()-COLUMN($B$8),_xlpm.m,(tblTasks[Due Date]=_xlpm.d)*(tblTasks[Visible]=1)*(tblTasks[Task]<>""),_xlpm.n,SUM(_xlpm.m),_xlpm.t,IF(_xlpm.n=0,"",_xlfn.TEXTJOIN(CHAR(10),TRUE,_xlfn.TAKE(_xlfn._xlws.FILTER(IF(tblTasks[State]="Overdue","⚠ ",IF(tblTasks[Status]=DoneStatus,"✓ ","• "))&tblTasks[Task],_xlpm.m),3))),DAY(_xlpm.d)&IF(_xlpm.d=TODAY()," · TODAY","")&IF(_xlpm.n=0,"",CHAR(10)&_xlpm.t&IF(_xlpm.n>3,CHAR(10)&"+"&(_xlpm.n-3)&" more","")))} -> 20 • Build new pricing page | D11: {=_xlfn.LET(_xlpm.d,CalStart+(ROW()-ROW($B$8))*7+COLUMN()-COLUMN($B$8),_xlpm.m,(tblTasks[Due Date]=_xlpm.d)*(tblTasks[Visible]=1)*(tblTasks[Task]<>""),_xlpm.n,SUM(_xlpm.m),_xlpm.t,IF(_xlpm.n=0,"",_xlfn.TEXTJOIN(CHAR(10),TRUE,_xlfn.TAKE(_xlfn._xlws.FILTER(IF(tblTasks[State]="Overdue","⚠ ",IF(tblTasks[Status]=DoneStatus,"✓ ","• "))&tblTasks[Task],_xlpm.m),3))),DAY(_xlpm.d)&IF(_xlpm.d=TODAY()," · TODAY","")&IF(_xlpm.n=0,"",CHAR(10)&_xlpm.t&IF(_xlpm.n>3,CHAR(10)&"+"&(_xlpm.n-3)&" more","")))} -> 21 • Offline sync engine • Onboarding success metrics | E11: {=_xlfn.LET(_xlpm.d,CalStart+(ROW()-ROW($B$8))*7+COLUMN()-COLUMN($B$8),_xlpm.m,(tblTasks[Due Date]=_xlpm.d)*(tblTasks[Visible]=1)*(tblTasks[Task]<>""),_xlpm.n,SUM(_xlpm.m),_xlpm.t,IF(_xlpm.n=0,"",_xlfn.TEXTJOIN(CHAR(10),TRUE,_xlfn.TAKE(_xlfn._xlws.FILTER(IF(tblTasks[State]="Overdue","⚠ ",IF(tblTasks[Status]=DoneStatus,"✓ ","• "))&tblTasks[Task],_xlpm.m),3))),DAY(_xlpm.d)&IF(_xlpm.d=TODAY()," · TODAY","")&IF(_xlpm.n=0,"",CHAR(10)&_xlpm.t&IF(_xlpm.n>3,CHAR(10)&"+"&(_xlpm.n-3)&" more","")))} -> 22 • Set up analytics events • Q4 hiring plan | F11: {=_xlfn.LET(_xlpm.d,CalStart+(ROW()-ROW($B$8))*7+COLUMN()-COLUMN($B$8),_xlpm.m,(tblTasks[Due Date]=_xlpm.d)*(tblTasks[Visible]=1)*(tblTasks[Task]<>""),_xlpm.n,SUM(_xlpm.m),_xlpm.t,IF(_xlpm.n=0,"",_xlfn.TEXTJOIN(CHAR(10),TRUE,_xlfn.TAKE(_xlfn._xlws.FILTER(IF(tblTasks[State]="Overdue","⚠ ",IF(tblTasks[Status]=DoneStatus,"✓ ","• "))&tblTasks[Task],_xlpm.m),3))),DAY(_xlpm.d)&IF(_xlpm.d=TODAY()," · TODAY","")&IF(_xlpm.n=0,"",CHAR(10)&_xlpm.t&IF(_xlpm.n>3,CHAR(10)&"+"&(_xlpm.n-3)&" more","")))} -> 23 • Holiday email sequence | G11: {=_xlfn.LET(_xlpm.d,CalStart+(ROW()-ROW($B$8))*7+COLUMN()-COLUMN($B$8),_xlpm.m,(tblTasks[Due Date]=_xlpm.d)*(tblTasks[Visible]=1)*(tblTasks[Task]<>""),_xlpm.n,SUM(_xlpm.m),_xlpm.t,IF(_xlpm.n=0,"",_xlfn.TEXTJOIN(CHAR(10),TRUE,_xlfn.TAKE(_xlfn._xlws.FILTER(IF(tblTasks[State]="Overdue","⚠ ",IF(tblTasks[Status]=DoneStatus,"✓ ","• "))&tblTasks[Task],_xlpm.m),3))),DAY(_xlpm.d)&IF(_xlpm.d=TODAY()," · TODAY","")&IF(_xlpm.n=0,"",CHAR(10)&_xlpm.t&IF(_xlpm.n>3,CHAR(10)&"+"&(_xlpm.n-3)&" more","")))} -> 24 • Regression test suite | H11: {=_xlfn.LET(_xlpm.d,CalStart+(ROW()-ROW($B$8))*7+COLUMN()-COLUMN($B$8),_xlpm.m,(tblTasks[Due Date]=_xlpm.d)*(tblTasks[Visible]=1)*(tblTasks[Task]<>""),_xlpm.n,SUM(_xlpm.m),_xlpm.t,IF(_xlpm.n=0,"",_xlfn.TEXTJOIN(CHAR(10),TRUE,_xlfn.TAKE(_xlfn._xlws.FILTER(IF(tblTasks[State]="Overdue","⚠ ",IF(tblTasks[Status]=DoneStatus,"✓ ","• "))&tblTasks[Task],_xlpm.m),3))),DAY(_xlpm.d)&IF(_xlpm.d=TODAY()," · TODAY","")&IF(_xlpm.n=0,"",CHAR(10)&_xlpm.t&IF(_xlpm.n>3,CHAR(10)&"+"&(_xlpm.n-3)&" more","")))} -> 25 • Migrate blog to new CMS
B12: {=_xlfn.LET(_xlpm.d,CalStart+(ROW()-ROW($B$8))*7+COLUMN()-COLUMN($B$8),_xlpm.m,(tblTasks[Due Date]=_xlpm.d)*(tblTasks[Visible]=1)*(tblTasks[Task]<>""),_xlpm.n,SUM(_xlpm.m),_xlpm.t,IF(_xlpm.n=0,"",_xlfn.TEXTJOIN(CHAR(10),TRUE,_xlfn.TAKE(_xlfn._xlws.FILTER(IF(tblTasks[State]="Overdue","⚠ ",IF(tblTasks[Status]=DoneStatus,"✓ ","• "))&tblTasks[Task],_xlpm.m),3))),DAY(_xlpm.d)&IF(_xlpm.d=TODAY()," · TODAY","")&IF(_xlpm.n=0,"",CHAR(10)&_xlpm.t&IF(_xlpm.n>3,CHAR(10)&"+"&(_xlpm.n-3)&" more","")))} -> 26 • App store screenshots • Welcome email series | C12: {=_xlfn.LET(_xlpm.d,CalStart+(ROW()-ROW($B$8))*7+COLUMN()-COLUMN($B$8),_xlpm.m,(tblTasks[Due Date]=_xlpm.d)*(tblTasks[Visible]=1)*(tblTasks[Task]<>""),_xlpm.n,SUM(_xlpm.m),_xlpm.t,IF(_xlpm.n=0,"",_xlfn.TEXTJOIN(CHAR(10),TRUE,_xlfn.TAKE(_xlfn._xlws.FILTER(IF(tblTasks[State]="Overdue","⚠ ",IF(tblTasks[Status]=DoneStatus,"✓ ","• "))&tblTasks[Task],_xlpm.m),3))),DAY(_xlpm.d)&IF(_xlpm.d=TODAY()," · TODAY","")&IF(_xlpm.n=0,"",CHAR(10)&_xlpm.t&IF(_xlpm.n>3,CHAR(10)&"+"&(_xlpm.n-3)&" more","")))} -> 27 • Paid ads creative • Release notes v2.0 | D12: {=_xlfn.LET(_xlpm.d,CalStart+(ROW()-ROW($B$8))*7+COLUMN()-COLUMN($B$8),_xlpm.m,(tblTasks[Due Date]=_xlpm.d)*(tblTasks[Visible]=1)*(tblTasks[Task]<>""),_xlpm.n,SUM(_xlpm.m),_xlpm.t,IF(_xlpm.n=0,"",_xlfn.TEXTJOIN(CHAR(10),TRUE,_xlfn.TAKE(_xlfn._xlws.FILTER(IF(tblTasks[State]="Overdue","⚠ ",IF(tblTasks[Status]=DoneStatus,"✓ ","• "))&tblTasks[Task],_xlpm.m),3))),DAY(_xlpm.d)&IF(_xlpm.d=TODAY()," · TODAY","")&IF(_xlpm.n=0,"",CHAR(10)&_xlpm.t&IF(_xlpm.n>3,CHAR(10)&"+"&(_xlpm.n-3)&" more","")))} -> 28 | E12: {=_xlfn.LET(_xlpm.d,CalStart+(ROW()-ROW($B$8))*7+COLUMN()-COLUMN($B$8),_xlpm.m,(tblTasks[Due Date]=_xlpm.d)*(tblTasks[Visible]=1)*(tblTasks[Task]<>""),_xlpm.n,SUM(_xlpm.m),_xlpm.t,IF(_xlpm.n=0,"",_xlfn.TEXTJOIN(CHAR(10),TRUE,_xlfn.TAKE(_xlfn._xlws.FILTER(IF(tblTasks[State]="Overdue","⚠ ",IF(tblTasks[Status]=DoneStatus,"✓ ","• "))&tblTasks[Task],_xlpm.m),3))),DAY(_xlpm.d)&IF(_xlpm.d=TODAY()," · TODAY","")&IF(_xlpm.n=0,"",CHAR(10)&_xlpm.t&IF(_xlpm.n>3,CHAR(10)&"+"&(_xlpm.n-3)&" more","")))} -> 29 • Press release draft | F12: {=_xlfn.LET(_xlpm.d,CalStart+(ROW()-ROW($B$8))*7+COLUMN()-COLUMN($B$8),_xlpm.m,(tblTasks[Due Date]=_xlpm.d)*(tblTasks[Visible]=1)*(tblTasks[Task]<>""),_xlpm.n,SUM(_xlpm.m),_xlpm.t,IF(_xlpm.n=0,"",_xlfn.TEXTJOIN(CHAR(10),TRUE,_xlfn.TAKE(_xlfn._xlws.FILTER(IF(tblTasks[State]="Overdue","⚠ ",IF(tblTasks[Status]=DoneStatus,"✓ ","• "))&tblTasks[Task],_xlpm.m),3))),DAY(_xlpm.d)&IF(_xlpm.d=TODAY()," · TODAY","")&IF(_xlpm.n=0,"",CHAR(10)&_xlpm.t&IF(_xlpm.n>3,CHAR(10)&"+"&(_xlpm.n-3)&" more","")))} -> 30 | G12: {=_xlfn.LET(_xlpm.d,CalStart+(ROW()-ROW($B$8))*7+COLUMN()-COLUMN($B$8),_xlpm.m,(tblTasks[Due Date]=_xlpm.d)*(tblTasks[Visible]=1)*(tblTasks[Task]<>""),_xlpm.n,SUM(_xlpm.m),_xlpm.t,IF(_xlpm.n=0,"",_xlfn.TEXTJOIN(CHAR(10),TRUE,_xlfn.TAKE(_xlfn._xlws.FILTER(IF(tblTasks[State]="Overdue","⚠ ",IF(tblTasks[Status]=DoneStatus,"✓ ","• "))&tblTasks[Task],_xlpm.m),3))),DAY(_xlpm.d)&IF(_xlpm.d=TODAY()," · TODAY","")&IF(_xlpm.n=0,"",CHAR(10)&_xlpm.t&IF(_xlpm.n>3,CHAR(10)&"+"&(_xlpm.n-3)&" more","")))} -> 31 • Accessibility audit • Collect department KPIs | H12: {=_xlfn.LET(_xlpm.d,CalStart+(ROW()-ROW($B$8))*7+COLUMN()-COLUMN($B$8),_xlpm.m,(tblTasks[Due Date]=_xlpm.d)*(tblTasks[Visible]=1)*(tblTasks[Task]<>""),_xlpm.n,SUM(_xlpm.m),_xlpm.t,IF(_xlpm.n=0,"",_xlfn.TEXTJOIN(CHAR(10),TRUE,_xlfn.TAKE(_xlfn._xlws.FILTER(IF(tblTasks[State]="Overdue","⚠ ",IF(tblTasks[Status]=DoneStatus,"✓ ","• "))&tblTasks[Task],_xlpm.m),3))),DAY(_xlpm.d)&IF(_xlpm.d=TODAY()," · TODAY","")&IF(_xlpm.n=0,"",CHAR(10)&_xlpm.t&IF(_xlpm.n>3,CHAR(10)&"+"&(_xlpm.n-3)&" more","")))} -> 1
B13: {=_xlfn.LET(_xlpm.d,CalStart+(ROW()-ROW($B$8))*7+COLUMN()-COLUMN($B$8),_xlpm.m,(tblTasks[Due Date]=_xlpm.d)*(tblTasks[Visible]=1)*(tblTasks[Task]<>""),_xlpm.n,SUM(_xlpm.m),_xlpm.t,IF(_xlpm.n=0,"",_xlfn.TEXTJOIN(CHAR(10),TRUE,_xlfn.TAKE(_xlfn._xlws.FILTER(IF(tblTasks[State]="Overdue","⚠ ",IF(tblTasks[Status]=DoneStatus,"✓ ","• "))&tblTasks[Task],_xlpm.m),3))),DAY(_xlpm.d)&IF(_xlpm.d=TODAY()," · TODAY","")&IF(_xlpm.n=0,"",CHAR(10)&_xlpm.t&IF(_xlpm.n>3,CHAR(10)&"+"&(_xlpm.n-3)&" more","")))} -> 2 • Security awareness training | C13: {=_xlfn.LET(_xlpm.d,CalStart+(ROW()-ROW($B$8))*7+COLUMN()-COLUMN($B$8),_xlpm.m,(tblTasks[Due Date]=_xlpm.d)*(tblTasks[Visible]=1)*(tblTasks[Task]<>""),_xlpm.n,SUM(_xlpm.m),_xlpm.t,IF(_xlpm.n=0,"",_xlfn.TEXTJOIN(CHAR(10),TRUE,_xlfn.TAKE(_xlfn._xlws.FILTER(IF(tblTasks[State]="Overdue","⚠ ",IF(tblTasks[Status]=DoneStatus,"✓ ","• "))&tblTasks[Task],_xlpm.m),3))),DAY(_xlpm.d)&IF(_xlpm.d=TODAY()," · TODAY","")&IF(_xlpm.n=0,"",CHAR(10)&_xlpm.t&IF(_xlpm.n>3,CHAR(10)&"+"&(_xlpm.n-3)&" more","")))} -> 3 | D13: {=_xlfn.LET(_xlpm.d,CalStart+(ROW()-ROW($B$8))*7+COLUMN()-COLUMN($B$8),_xlpm.m,(tblTasks[Due Date]=_xlpm.d)*(tblTasks[Visible]=1)*(tblTasks[Task]<>""),_xlpm.n,SUM(_xlpm.m),_xlpm.t,IF(_xlpm.n=0,"",_xlfn.TEXTJOIN(CHAR(10),TRUE,_xlfn.TAKE(_xlfn._xlws.FILTER(IF(tblTasks[State]="Overdue","⚠ ",IF(tblTasks[Status]=DoneStatus,"✓ ","• "))&tblTasks[Task],_xlpm.m),3))),DAY(_xlpm.d)&IF(_xlpm.d=TODAY()," · TODAY","")&IF(_xlpm.n=0,"",CHAR(10)&_xlpm.t&IF(_xlpm.n>3,CHAR(10)&"+"&(_xlpm.n-3)&" more","")))} -> 4 • Influencer shortlist | E13: {=_xlfn.LET(_xlpm.d,CalStart+(ROW()-ROW($B$8))*7+COLUMN()-COLUMN($B$8),_xlpm.m,(tblTasks[Due Date]=_xlpm.d)*(tblTasks[Visible]=1)*(tblTasks[Task]<>""),_xlpm.n,SUM(_xlpm.m),_xlpm.t,IF(_xlpm.n=0,"",_xlfn.TEXTJOIN(CHAR(10),TRUE,_xlfn.TAKE(_xlfn._xlws.FILTER(IF(tblTasks[State]="Overdue","⚠ ",IF(tblTasks[Status]=DoneStatus,"✓ ","• "))&tblTasks[Task],_xlpm.m),3))),DAY(_xlpm.d)&IF(_xlpm.d=TODAY()," · TODAY","")&IF(_xlpm.n=0,"",CHAR(10)&_xlpm.t&IF(_xlpm.n>3,CHAR(10)&"+"&(_xlpm.n-3)&" more","")))} -> 5 | F13: {=_xlfn.LET(_xlpm.d,CalStart+(ROW()-ROW($B$8))*7+COLUMN()-COLUMN($B$8),_xlpm.m,(tblTasks[Due Date]=_xlpm.d)*(tblTasks[Visible]=1)*(tblTasks[Task]<>""),_xlpm.n,SUM(_xlpm.m),_xlpm.t,IF(_xlpm.n=0,"",_xlfn.TEXTJOIN(CHAR(10),TRUE,_xlfn.TAKE(_xlfn._xlws.FILTER(IF(tblTasks[State]="Overdue","⚠ ",IF(tblTasks[Status]=DoneStatus,"✓ ","• "))&tblTasks[Task],_xlpm.m),3))),DAY(_xlpm.d)&IF(_xlpm.d=TODAY()," · TODAY","")&IF(_xlpm.n=0,"",CHAR(10)&_xlpm.t&IF(_xlpm.n>3,CHAR(10)&"+"&(_xlpm.n-3)&" more","")))} -> 6 • In-app product tour | G13: {=_xlfn.LET(_xlpm.d,CalStart+(ROW()-ROW($B$8))*7+COLUMN()-COLUMN($B$8),_xlpm.m,(tblTasks[Due Date]=_xlpm.d)*(tblTasks[Visible]=1)*(tblTasks[Task]<>""),_xlpm.n,SUM(_xlpm.m),_xlpm.t,IF(_xlpm.n=0,"",_xlfn.TEXTJOIN(CHAR(10),TRUE,_xlfn.TAKE(_xlfn._xlws.FILTER(IF(tblTasks[State]="Overdue","⚠ ",IF(tblTasks[Status]=DoneStatus,"✓ ","• "))&tblTasks[Task],_xlpm.m),3))),DAY(_xlpm.d)&IF(_xlpm.d=TODAY()," · TODAY","")&IF(_xlpm.n=0,"",CHAR(10)&_xlpm.t&IF(_xlpm.n>3,CHAR(10)&"+"&(_xlpm.n-3)&" more","")))} -> 7 | H13: {=_xlfn.LET(_xlpm.d,CalStart+(ROW()-ROW($B$8))*7+COLUMN()-COLUMN($B$8),_xlpm.m,(tblTasks[Due Date]=_xlpm.d)*(tblTasks[Visible]=1)*(tblTasks[Task]<>""),_xlpm.n,SUM(_xlpm.m),_xlpm.t,IF(_xlpm.n=0,"",_xlfn.TEXTJOIN(CHAR(10),TRUE,_xlfn.TAKE(_xlfn._xlws.FILTER(IF(tblTasks[State]="Overdue","⚠ ",IF(tblTasks[Status]=DoneStatus,"✓ ","• "))&tblTasks[Task],_xlpm.m),3))),DAY(_xlpm.d)&IF(_xlpm.d=TODAY()," · TODAY","")&IF(_xlpm.n=0,"",CHAR(10)&_xlpm.t&IF(_xlpm.n>3,CHAR(10)&"+"&(_xlpm.n-3)&" more","")))} -> 8 • Launch-day checklist
B16: 🗓 Coming up - next 14 days
B17: DUE | C17: PRIORITY | D17: OWNER | E17: STATUS | F17: PROJECT | G17: TASK
B18: {=_xlfn.LET(_xlpm.m,(tblTasks[Visible]=1)*(tblTasks[Status]<>DoneStatus)*ISNUMBER(tblTasks[Due Date])*(tblTasks[Due Date]>=TODAY())*(tblTasks[Due Date]<=TODAY()+14),IFERROR(_xlfn.SORTBY(_xlfn._xlws.FILTER(_xlfn.HSTACK(tblTasks[Due Date],tblTasks[Priority],tblTasks[Owner],tblTasks[Status],tblTasks[Project],tblTasks[Task]),_xlpm.m),_xlfn._xlws.FILTER(tblTasks[DueKey],_xlpm.m),1),"Nothing due in the next two weeks"))} -> 46312 | C18: High | D18: Omar Haddad | E18: Review | F18: Mobile App v2 | G18: Push notification service
B19: 46312 | C19: Normal | D19: Sara Ali | E19: Done | F19: Annual Report 2026 | G19: Kickoff & timeline
B20: 46313 | C20: Normal | D20: Aisha Bello | E20: Review | F20: Website Redesign | G20: Write pricing page copy
B21: 46313 | C21: Urgent | D21: Ravi Kumar | E21: In Progress | F21: General / Ops | G21: Vendor contract renewal
B22: 46313 | C22: High | D22: Maya Chen | E22: Back Log | F22: ExCon | G22: 1st Priority task
B23: 46314 | C23: Normal | D23: Lina Park | E23: Review | F23: Q4 Marketing Campaign | G23: Social media calendar
B24: 46314 | C24: Normal | D24: Maya Chen | E24: In Progress | F24: Customer Onboarding | G24: Customer interview round
B25: 46315 | C25: High | D25: Diego Santos | E25: In Progress | F25: Website Redesign | G25: Build new pricing page
B26: 46316 | C26: Urgent | D26: Omar Haddad | E26: In Progress | F26: Mobile App v2 | G26: Offline sync engine
B27: 46316 | C27: Normal | D27: Jack Moore | E27: Review | F27: Customer Onboarding | G27: Onboarding success metrics
B28: 46317 | C28: Normal | D28: Jack Moore | E28: In Progress | F28: Website Redesign | G28: Set up analytics events
B29: 46317 | C29: High | D29: Sara Ali | E29: Review | F29: General / Ops | G29: Q4 hiring plan
B30: 46318 | C30: High | D30: Aisha Bello | E30: In Progress | F30: Q4 Marketing Campaign | G30: Holiday email sequence
... B39: 46326 | C39: High | D39: Ravi Kumar | E39: To Do | F39: Annual Report 2026 | G39: Collect department KPIs

Sheet Scorecards
B2: Scorecards | U2: ⌂ Home
B3: Who's delivering, which projects are healthy · score = 50% completion + 30% on-time + 20% not overdue
B6: 🏆 Team scorecard
B7: MEMBER | C7: ASSIGNED | D7: DONE | E7: OPEN | F7: OVERDUE | G7: COMPLETION | H7: ON-TIME | I7: SCORE | J7: RATING | K7: RANK | L7: BADGE
B8: {=lstMembers} -> Sara Ali | C8: {=COUNTIFS(tblTasks[Owner],_xlfn.ANCHORARRAY(B8),tblTasks[Visible],1)} -> 4 | D8: {=COUNTIFS(tblTasks[Owner],_xlfn.ANCHORARRAY(B8),tblTasks[Visible],1,tblTasks[Status],DoneStatus)} -> 0 | E8: {=_xlfn.ANCHORARRAY(C8)-_xlfn.ANCHORARRAY(D8)} -> 4 | F8: {=COUNTIFS(tblTasks[Owner],_xlfn.ANCHORARRAY(B8),tblTasks[Visible],1,tblTasks[State],"Overdue")} -> 1 | G8: {=IF(_xlfn.ANCHORARRAY(C8)=0,"",_xlfn.ANCHORARRAY(D8)/_xlfn.ANCHORARRAY(C8))} -> 0 | H8: {=IFERROR(SUMIFS(tblTasks[On Time],tblTasks[Owner],_xlfn.ANCHORARRAY(B8),tblTasks[Visible],1)/COUNTIFS(tblTasks[Owner],_xlfn.ANCHORARRAY(B8),tblTasks[Visible],1,tblTasks[On Time],">=0"),"")} | I8: {=_xlfn.LET(_xlpm.a,_xlfn.ANCHORARRAY(C8),_xlpm.comp,IFERROR(_xlfn.ANCHORARRAY(D8)/_xlpm.a,0),_xlpm.ot,IFERROR(_xlfn.ANCHORARRAY(H8)*1,_xlpm.comp),_xlpm.od,IFERROR(1-_xlfn.ANCHORARRAY(F8)/_xlfn.ANCHORARRAY(E8),1),IF(_xlpm.a=0,"",ROUND(100*(0.5*_xlpm.comp+0.3*_xlpm.ot+0.2*_xlpm.od),0)))} -> 15 | J8: {=IF(_xlfn.ANCHORARRAY(I8)="","",REPT("★",ROUND(_xlfn.ANCHORARRAY(I8)/20,0))&REPT("☆",5-ROUND(_xlfn.ANCHORARRAY(I8)/20,0)))} -> ★☆☆☆☆ | K8: {=IF(_xlfn.ANCHORARRAY(I8)="","",_xlfn.XMATCH(_xlfn.ANCHORARRAY(I8),_xlfn._xlws.SORT(_xlfn._xlws.FILTER(_xlfn.ANCHORARRAY(I8),_xlfn.ANCHORARRAY(I8)<>""),,-1)))} -> 3 | L8: {=IF(_xlfn.ANCHORARRAY(K8)="","",IF(_xlfn.ANCHORARRAY(K8)=1,"🥇 MVP",IF(_xlfn.ANCHORARRAY(K8)=2,"🥈 2nd",IF(_xlfn.ANCHORARRAY(K8)=3,"🥉 3rd",IF(N(_xlfn.ANCHORARRAY(I8))>=80,"🔥 Strong","")))))} -> 🥉 3rd
B9: Omar Haddad | C9: 2 | D9: 0 | E9: 2 | F9: 0 | G9: 0 | I9: 20 | J9: ★☆☆☆☆ | K9: 1 | L9: 🥇 MVP
B10: Lina Park | C10: 3 | D10: 0 | E10: 3 | F10: 1 | G10: 0 | I10: 13 | J10: ★☆☆☆☆ | K10: 5
B11: Jack Moore | C11: 5 | D11: 0 | E11: 5 | F11: 3 | G11: 0 | I11: 8 | J11: ☆☆☆☆☆ | K11: 10
B12: Maya Chen | C12: 4 | D12: 0 | E12: 4 | F12: 2 | G12: 0 | I12: 10 | J12: ★☆☆☆☆ | K12: 8
B13: Ravi Kumar | C13: 3 | D13: 0 | E13: 3 | F13: 1 | G13: 0 | I13: 13 | J13: ★☆☆☆☆ | K13: 5
B14: Nora Fischer | C14: 6 | D14: 0 | E14: 6 | F14: 2 | G14: 0 | I14: 13 | J14: ★☆☆☆☆ | K14: 5
B15: Diego Santos | C15: 4 | D15: 0 | E15: 4 | F15: 1 | G15: 0 | I15: 15 | J15: ★☆☆☆☆ | K15: 3 | L15: 🥉 3rd
B16: Aisha Bello | C16: 6 | D16: 0 | E16: 6 | F16: 0 | G16: 0 | I16: 20 | J16: ★☆☆☆☆ | K16: 1 | L16: 🥇 MVP
B17: Tom Becker | C17: 4 | D17: 0 | E17: 4 | F17: 2 | G17: 0 | I17: 10 | J17: ★☆☆☆☆ | K17: 8
B25: 📁 Project scorecard
B26: PROJECT | C26: CODE | D26: OWNER | E26: TASKS | F26: DONE | G26: PROGRESS | H26: OVERDUE | I26: DAYS LEFT | J26: TARGET | K26: HEALTH
B27: {=IFERROR(_xlfn.HSTACK(tblProjects[Project],tblProjects[Code],tblProjects[Owner],tblProjects[Tasks],tblProjects[Done],tblProjects[Progress],tblProjects[Overdue],tblProjects[Days Left],tblProjects[Target Date],tblProjects[Health]),"")} -> Website Redesign | C27: WEB | D27: Sara Ali | E27: 9 | F27: 0 | G27: 0 | H27: 3 | I27: 25 | J27: 46337 | K27: ⛔ Off Track
B28: Q4 Marketing Campaign | C28: MKT | D28: Lina Park | E28: 8 | F28: 0 | G28: 0 | H28: 3 | I28: 45 | J28: 46357 | K28: ⛔ Off Track
B29: Mobile App v2 | C29: APP | D29: Omar Haddad | E29: 8 | F29: 0 | G29: 0 | H29: 3 | I29: 10 | J29: 46322 | K29: ⛔ Off Track
B30: Customer Onboarding | C30: ONB | D30: Maya Chen | E30: 6 | F30: 0 | G30: 0 | H30: 1 | I30: 60 | J30: 46372 | K30: ⚠ At Risk
B31: General / Ops | C31: OPS | D31: Sara Ali | E31: 6 | F31: 0 | G31: 0 | H31: 3 | I31: 90 | J31: 46402 | K31: ⛔ Off Track
B32: Annual Report 2026 | C32: RPT | D32: Ravi Kumar | E32: 3 | F32: 0 | G32: 0 | H32: 0 | I32: 70 | J32: 46382 | K32: ✅ On Track
B33: ExCon | C33: UPA | D33: Maya Chen | E33: 1 | F33: 0 | G33: 0 | H33: 0 | I33: 92 | J33: 46404 | K33: ✅ On Track

Sheet Projects
B2: Projects | P2: ⌂ Home
B3: Every project the team runs. Add a row at the bottom - it appears in the Room instantly.
B4: Blue headers = you type (Code = 2-4 letters shown on cards). Grey headers = calculated automatically.
B5: Project | C5: Code | D5: Owner | E5: Start Date | F5: Target Date | G5: Description | H5: Added By | I5: Added On | J5: Tasks | K5: Done | L5: Progress | M5: Overdue | N5: Days Left | O5: Health
B6: Website Redesign | C6: WEB | D6: Sara Ali | E6: 46272 | F6: 46337 | G6: New brand look, faster pages and a smoother signup flow | H6: Sara Ali | I6: 46270 | J6: =COUNTIFS(tblTasks[Project],tblProjects[[#This Row],[Project]]) -> 9 | K6: {=COUNTIFS(tblTasks[Project],tblProjects[[#This Row],[Project]],tblTasks[Status],DoneStatus)} -> 0 | L6: =IF(tblProjects[[#This Row],[Tasks]]=0,0,tblProjects[[#This Row],[Done]]/tblProjects[[#This Row],[Tasks]]) -> 0 | M6: =COUNTIFS(tblTasks[Project],tblProjects[[#This Row],[Project]],tblTasks[State],"Overdue") -> 3 | N6: =IF(tblProjects[[#This Row],[Target Date]]="","",tblProjects[[#This Row],[Target Date]]-TODAY()) -> 25 | O6: =IF(tblProjects[[#This Row],[Project]]="","",IF(AND(tblProjects[[#This Row],[Tasks]]>0,tblProjects[[#This Row],[Done]]=tblProjects[[#This Row],[Tasks]]),"🏁 Complete",_xlfn.LET(_xlpm.expected,IF(OR(tblProjects[[#This Row],[Start Date]]="",tblProjects[[#This Row],[Target Date]]="",N(tblProjects[[#This Row],[Target Date]])<=N(tblProjects[[#This Row],[Start Date]])),0,MIN(1,MAX(0,(TODAY()-tblProjects[[#This Row],[Start Date]])/(tblProjects[[#This Row],[Target Date]]-tblProjects[[#This Row],[Start Date]])))),IF(OR(tblProjects[[#This Row],[Overdue]]>=3,AND(ISNUMBER(tblProjects[[#This Row],[Days Left]]),N(tblProjects[[#This Row],[Days Left]])<0)),"⛔ Off Track",IF(OR(tblProjects[[#This Row],[Overdue]]>=1,tblProjects[[#This Row],[Progress]]<_xlpm.expected-0.25),"⚠ At Risk","✅ On Track"))))) -> ⛔ Off Track
B7: Q4 Marketing Campaign | C7: MKT | D7: Lina Park | E7: 46282 | F7: 46357 | G7: Holiday campaign across email, social and paid ads | H7: Lina Park | I7: 46281 | J7: =COUNTIFS(tblTasks[Project],tblProjects[[#This Row],[Project]]) -> 8 | K7: {=COUNTIFS(tblTasks[Project],tblProjects[[#This Row],[Project]],tblTasks[Status],DoneStatus)} -> 0 | L7: =IF(tblProjects[[#This Row],[Tasks]]=0,0,tblProjects[[#This Row],[Done]]/tblProjects[[#This Row],[Tasks]]) -> 0 | M7: =COUNTIFS(tblTasks[Project],tblProjects[[#This Row],[Project]],tblTasks[State],"Overdue") -> 3 | N7: =IF(tblProjects[[#This Row],[Target Date]]="","",tblProjects[[#This Row],[Target Date]]-TODAY()) -> 45 | O7: =IF(tblProjects[[#This Row],[Project]]="","",IF(AND(tblProjects[[#This Row],[Tasks]]>0,tblProjects[[#This Row],[Done]]=tblProjects[[#This Row],[Tasks]]),"🏁 Complete",_xlfn.LET(_xlpm.expected,IF(OR(tblProjects[[#This Row],[Start Date]]="",tblProjects[[#This Row],[Target Date]]="",N(tblProjects[[#This Row],[Target Date]])<=N(tblProjects[[#This Row],[Start Date]])),0,MIN(1,MAX(0,(TODAY()-tblProjects[[#This Row],[Start Date]])/(tblProjects[[#This Row],[Target Date]]-tblProjects[[#This Row],[Start Date]])))),IF(OR(tblProjects[[#This Row],[Overdue]]>=3,AND(ISNUMBER(tblProjects[[#This Row],[Days Left]]),N(tblProjects[[#This Row],[Days Left]])<0)),"⛔ Off Track",IF(OR(tblProjects[[#This Row],[Overdue]]>=1,tblProjects[[#This Row],[Progress]]<_xlpm.expected-0.25),"⚠ At Risk","✅ On Track"))))) -> ⛔ Off Track
B8: Mobile App v2 | C8: APP | D8: Omar Haddad | E8: 46252 | F8: 46322 | G8: Offline mode, push notifications and dark theme | H8: Omar Haddad | I8: 46251 | J8: =COUNTIFS(tblTasks[Project],tblProjects[[#This Row],[Project]]) -> 8 | K8: {=COUNTIFS(tblTasks[Project],tblProjects[[#This Row],[Project]],tblTasks[Status],DoneStatus)} -> 0 | L8: =IF(tblProjects[[#This Row],[Tasks]]=0,0,tblProjects[[#This Row],[Done]]/tblProjects[[#This Row],[Tasks]]) -> 0 | M8: =COUNTIFS(tblTasks[Project],tblProjects[[#This Row],[Project]],tblTasks[State],"Overdue") -> 3 | N8: =IF(tblProjects[[#This Row],[Target Date]]="","",tblProjects[[#This Row],[Target Date]]-TODAY()) -> 10 | O8: =IF(tblProjects[[#This Row],[Project]]="","",IF(AND(tblProjects[[#This Row],[Tasks]]>0,tblProjects[[#This Row],[Done]]=tblProjects[[#This Row],[Tasks]]),"🏁 Complete",_xlfn.LET(_xlpm.expected,IF(OR(tblProjects[[#This Row],[Start Date]]="",tblProjects[[#This Row],[Target Date]]="",N(tblProjects[[#This Row],[Target Date]])<=N(tblProjects[[#This Row],[Start Date]])),0,MIN(1,MAX(0,(TODAY()-tblProjects[[#This Row],[Start Date]])/(tblProjects[[#This Row],[Target Date]]-tblProjects[[#This Row],[Start Date]])))),IF(OR(tblProjects[[#This Row],[Overdue]]>=3,AND(ISNUMBER(tblProjects[[#This Row],[Days Left]]),N(tblProjects[[#This Row],[Days Left]])<0)),"⛔ Off Track",IF(OR(tblProjects[[#This Row],[Overdue]]>=1,tblProjects[[#This Row],[Progress]]<_xlpm.expected-0.25),"⚠ At Risk","✅ On Track"))))) -> ⛔ Off Track
B9: Customer Onboarding | C9: ONB | D9: Maya Chen | E9: 46292 | F9: 46372 | G9: Cut time-to-first-value from 14 to 5 days | H9: Maya Chen | I9: 46292 | J9: =COUNTIFS(tblTasks[Project],tblProjects[[#This Row],[Project]]) -> 6 | K9: {=COUNTIFS(tblTasks[Project],tblProjects[[#This Row],[Project]],tblTasks[Status],DoneStatus)} -> 0 | L9: =IF(tblProjects[[#This Row],[Tasks]]=0,0,tblProjects[[#This Row],[Done]]/tblProjects[[#This Row],[Tasks]]) -> 0 | M9: =COUNTIFS(tblTasks[Project],tblProjects[[#This Row],[Project]],tblTasks[State],"Overdue") -> 1 | N9: =IF(tblProjects[[#This Row],[Target Date]]="","",tblProjects[[#This Row],[Target Date]]-TODAY()) -> 60 | O9: =IF(tblProjects[[#This Row],[Project]]="","",IF(AND(tblProjects[[#This Row],[Tasks]]>0,tblProjects[[#This Row],[Done]]=tblProjects[[#This Row],[Tasks]]),"🏁 Complete",_xlfn.LET(_xlpm.expected,IF(OR(tblProjects[[#This Row],[Start Date]]="",tblProjects[[#This Row],[Target Date]]="",N(tblProjects[[#This Row],[Target Date]])<=N(tblProjects[[#This Row],[Start Date]])),0,MIN(1,MAX(0,(TODAY()-tblProjects[[#This Row],[Start Date]])/(tblProjects[[#This Row],[Target Date]]-tblProjects[[#This Row],[Start Date]])))),IF(OR(tblProjects[[#This Row],[Overdue]]>=3,AND(ISNUMBER(tblProjects[[#This Row],[Days Left]]),N(tblProjects[[#This Row],[Days Left]])<0)),"⛔ Off Track",IF(OR(tblProjects[[#This Row],[Overdue]]>=1,tblProjects[[#This Row],[Progress]]<_xlpm.expected-0.25),"⚠ At Risk","✅ On Track"))))) -> ⚠ At Risk
